Workbook

Sheet Discard Log
A1: Date | B1: Food Item | C1: Quantity (Units) | D1: Discard Reason | E1: Donatable? | F1: Conditions (if any) | G1: POTENTIAL REVENUE LOST
A2: 45719 | B2: ING-061 | C2: 1 | D2: Hot Hold | E2: Maybe | F2: Temp. logs req. | G2: =IFERROR(VLOOKUP(B2, 'Price Data'!A:D, 3, FALSE) * VLOOKUP(B2, 'Price Data'!A:D, 4, FALSE) * C2, "")
A3: 45719 | B3: ING-028 | C3: 4 | D3: Hot Hold | E3: No | F3: No Date | Temp. logs req. | G3: =IFERROR(VLOOKUP(B3, 'Price Data'!A:D, 3, FALSE) * VLOOKUP(B3, 'Price Data'!A:D, 4, FALSE) * C3, "")
A4: 45719 | B4: ING-157 | C4: 9.5 | D4: Hot Hold | E4: Maybe | F4: Temp. logs req. | G4: =IFERROR(VLOOKUP(B4, 'Price Data'!A:D, 3, FALSE) * VLOOKUP(B4, 'Price Data'!A:D, 4, FALSE) * C4, "")
A5: 45719 | B5: ING-185 | C5: 0.5 | D5: Expiring | E5: Maybe | F5: No tamper-proof seal, Freeze (req) | G5: =IFERROR(VLOOKUP(B5, 'Price Data'!A:D, 3, FALSE) * VLOOKUP(B5, 'Price Data'!A:D, 4, FALSE) * C5, "")
A6: 45719 | B6: ING-072 | C6: 1 | D6: Hot Hold | E6: Maybe | F6: Temp. logs req. | G6: =IFERROR(VLOOKUP(B6, 'Price Data'!A:D, 3, FALSE) * VLOOKUP(B6, 'Price Data'!A:D, 4, FALSE) * C6, "")
A7: 45719 | B7: ING-049 | C7: 2.5 | D7: Hot Hold | E7: No | F7: Minimal Utility | G7: =IFERROR(VLOOKUP(B7, 'Price Data'!A:D, 3, FALSE) * VLOOKUP(B7, 'Price Data'!A:D, 4, FALSE) * C7, "")
A8: 45719 | B8: ING-129 | C8: 1.5 | D8: Hot Hold | E8: Maybe | F8: Temp. logs req. | G8: =IFERROR(VLOOKUP(B8, 'Price Data'!A:D, 3, FALSE) * VLOOKUP(B8, 'Price Data'!A:D, 4, FALSE) * C8, "")
A9: 45719 | B9: ING-034 | C9: 2.5 | D9: Expiring | E9: Yes | F9: As is | G9: =IFERROR(VLOOKUP(B9, 'Price Data'!A:D, 3, FALSE) * VLOOKUP(B9, 'Price Data'!A:D, 4, FALSE) * C9, "")
A10: 45719 | B10: ING-105 | C10: 2 | D10: Hot Hold | E10: Weak Maybe | F10: Temp. logs req. | Minimal Utility | G10: =IFERROR(VLOOKUP(B10, 'Price Data'!A:D, 3, FALSE) * VLOOKUP(B10, 'Price Data'!A:D, 4, FALSE) * C10, "")
A11: 45719 | B11: ING-172 | C11: 3.5 | D11: Expiring | E11: Yes | F11: Freeze (rec) | G11: =IFERROR(VLOOKUP(B11, 'Price Data'!A:D, 3, FALSE) * VLOOKUP(B11, 'Price Data'!A:D, 4, FALSE) * C11, "")
A12: 45719 | B12: ING-021 | C12: 3.5 | D12: Hot Hold | E12: Maybe | F12: Temp. logs req. | G12: =IFERROR(VLOOKUP(B12, 'Price Data'!A:D, 3, FALSE) * VLOOKUP(B12, 'Price Data'!A:D, 4, FALSE) * C12, "")
A13: 45719 | B13: ING-148 | C13: 1 | D13: Hot Hold | E13: Maybe | F13: Temp. logs req. | G13: =IFERROR(VLOOKUP(B13, 'Price Data'!A:D, 3, FALSE) * VLOOKUP(B13, 'Price Data'!A:D, 4, FALSE) * C13, "")
... A152: 45726 | B152: ING-148 | C152: 1 | D152: Hot Hold | E152: Maybe | F152: Temp. logs req. | G152: =IFERROR(VLOOKUP(B152, 'Price Data'!A:D, 3, FALSE) * VLOOKUP(B152, 'Price Data'!A:D, 4, FALSE) * C152, "")
A153: 45730 | B153: ING-066 | C153: 0.5 | D153: DISCARDED | E153: No | F153: N/A | G153: =IFERROR(ROUND(VLOOKUP(B153, 'Price Data'!A:D, 3, FALSE) * VLOOKUP(B153, 'Price Data'!A:D, 4, FALSE) * C153, 2), "")
A154: 45730 | B154: ING-027 | C154: 1.5 | D154: Expiring | E154: No | F154: Minimal Utility | G154: =IFERROR(VLOOKUP(B154, 'Price Data'!A:D, 3, FALSE) * VLOOKUP(B154, 'Price Data'!A:D, 4, FALSE) * C154, "")
A155: 45730 | B155: ING-015 | C155: 0.5 | D155: Expiring | E155: No | F155: No tamper-proof seal | G155: =IFERROR(VLOOKUP(B155, 'Price Data'!A:D, 3, FALSE) * VLOOKUP(B155, 'Price Data'!A:D, 4, FALSE) * C155, "")
A156: 45730 | B156: ING-150 | C156: 19 | D156: Expiring | E156: Yes | F156: Freeze (req) | G156: =IFERROR(VLOOKUP(B156, 'Price Data'!A:D, 3, FALSE) * VLOOKUP(B156, 'Price Data'!A:D, 4, FALSE) * C156, "")
A157: 45730 | B157: ING-159 | C157: 1.5 | D157: Hot Hold | E157: Maybe | F157: Freeze (req) | G157: =IFERROR(VLOOKUP(B157, 'Price Data'!A:D, 3, FALSE) * VLOOKUP(B157, 'Price Data'!A:D, 4, FALSE) * C157, "")
A158: 45730 | B158: ING-076 | C158: 2.5 | D158: Expiring | E158: Yes | F158: As is | G158: =IFERROR(VLOOKUP(B158, 'Price Data'!A:D, 3, FALSE) * VLOOKUP(B158, 'Price Data'!A:D, 4, FALSE) * C158, "")
A159: 45730 | B159: ING-028 | C159: 7 | D159: Hot Hold | E159: No | F159: No Date | Temp. logs req. | G159: =IFERROR(VLOOKUP(B159, 'Price Data'!A:D, 3, FALSE) * VLOOKUP(B159, 'Price Data'!A:D, 4, FALSE) * C159, "")
A160: 45730 | B160: ING-157 | C160: 20.5 | D160: Expiring | E160: Yes | F160: As is | G160: =IFERROR(VLOOKUP(B160, 'Price Data'!A:D, 3, FALSE) * VLOOKUP(B160, 'Price Data'!A:D, 4, FALSE) * C160, "")
A161: 45730 | B161: ING-152 | C161: 1 | D161: Hot Hold | E161: Weak Maybe | F161: Temp. logs req. | G161: =IFERROR(VLOOKUP(B161, 'Price Data'!A:D, 3, FALSE) * VLOOKUP(B161, 'Price Data'!A:D, 4, FALSE) * C161, "")
A162: 45730 | B162: ING-072 | C162: 1 | D162: Hot Hold | E162: Maybe | F162: Freeze (req) | G162: =IFERROR(VLOOKUP(B162, 'Price Data'!A:D, 3, FALSE) * VLOOKUP(B162, 'Price Data'!A:D, 4, FALSE) * C162, "")
A163: 45730 | B163: ING-146 | C163: 1 | D163: Hot Hold | E163: Weak Maybe | F163: Temp. logs req. | G163: =IFERROR(VLOOKUP(B163, 'Price Data'!A:D, 3, FALSE) * VLOOKUP(B163, 'Price Data'!A:D, 4, FALSE) * C163, "")
A164: 45730 | B164: ING-016 | C164: 2.5 | D164: Expiring | E164: Strong Maybe | F164: Freeze (req) | Seafood | G164: =IFERROR(VLOOKUP(B164, 'Price Data'!A:D, 3, FALSE) * VLOOKUP(B164, 'Price Data'!A:D, 4, FALSE) * C164, "")
A165: 45730 | B165: ING-100 | C165: 1.5 | D165: Expiring | E165: Weak Maybe | F165: As is | G165: =IFERROR(VLOOKUP(B165, 'Price Data'!A:D, 3, FALSE) * VLOOKUP(B165, 'Price Data'!A:D, 4, FALSE) * C165, "")
... A244: 45736 | B244: ING-172 | C244: 2.5 | D244: Expiring | E244: Yes | F244: Freeze (rec) | G244: =IFERROR(VLOOKUP(B244, 'Price Data'!A:D, 3, FALSE) * VLOOKUP(B244, 'Price Data'!A:D, 4, FALSE) * C244, "")
A245: 45736 | B245: ING-019 | C245: 0.5 | D245: Expiring | E245: No | G245: =IFERROR(VLOOKUP(B245, 'Price Data'!A:D, 3, FALSE) * VLOOKUP(B245, 'Price Data'!A:D, 4, FALSE) * C245, "")
A246: 45736 | B246: ING-152 | C246: 1 | D246: Hot Hold | E246: Weak Maybe | F246: Temp. logs req. | G246: =IFERROR(VLOOKUP(B246, 'Price Data'!A:D, 3, FALSE) * VLOOKUP(B246, 'Price Data'!A:D, 4, FALSE) * C246, "")
A247: 45736 | B247: ING-056 | C247: 1 | D247: Hot Hold | E247: No | F247: Temp. logs req. | Cooked produce | Minimal Utility | G247: =IFERROR(VLOOKUP(B247, 'Price Data'!A:D, 3, FALSE) * VLOOKUP(B247, 'Price Data'!A:D, 4, FALSE) * C247, "")
A248: 45736 | B248: ING-076 | C248: 1.5 | D248: Hot Hold | E248: Weak Maybe | F248: Temp. logs req. | G248: =IFERROR(VLOOKUP(B248, 'Price Data'!A:D, 3, FALSE) * VLOOKUP(B248, 'Price Data'!A:D, 4, FALSE) * C248, "")
A249: 45736 | B249: ING-159 | C249: 2.5 | D249: Hot Hold | E249: Maybe | F249: Temp. logs req. | G249: =IFERROR(VLOOKUP(B249, 'Price Data'!A:D, 3, FALSE) * VLOOKUP(B249, 'Price Data'!A:D, 4, FALSE) * C249, "")
A250: 45736 | B250: ING-049 | C250: 0.5 | D250: Hot Hold | E250: No | F250: Minimal Utility | G250: =IFERROR(VLOOKUP(B250, 'Price Data'!A:D, 3, FALSE) * VLOOKUP(B250, 'Price Data'!A:D, 4, FALSE) * C250, "")
A251: 45736 | B251: ING-016 | C251: 1 | D251: Expiring | E251: Strong Maybe | F251: Freeze (req) | Seafood | G251: =IFERROR(VLOOKUP(B251, 'Price Data'!A:D, 3, FALSE) * VLOOKUP(B251, 'Price Data'!A:D, 4, FALSE) * C251, "")
A252: 45736 | B252: ING-129 | C252: 1 | D252: Hot Hold | E252: Maybe | F252: Temp. logs req. | G252: =IFERROR(VLOOKUP(B252, 'Price Data'!A:D, 3, FALSE) * VLOOKUP(B252, 'Price Data'!A:D, 4, FALSE) * C252, "")
A253: 45736 | B253: ING-145 | C253: 1 | D253: Hot Hold | E253: Maybe | F253: Temp. logs req. | G253: =IFERROR(VLOOKUP(B253, 'Price Data'!A:D, 3, FALSE) * VLOOKUP(B253, 'Price Data'!A:D, 4, FALSE) * C253, "")
A254: 45736 | B254: ING-055 | C254: 5 | D254: Expiring | E254: Yes | F254: Freeze (rec) | G254: =IFERROR(VLOOKUP(B254, 'Price Data'!A:D, 3, FALSE) * VLOOKUP(B254, 'Price Data'!A:D, 4, FALSE) * C254, "")
A255: 45736 | B255: ING-045 | C255: 2 | D255: Expiring | E255: Strong Maybe | F255: Cut produce | As is | G255: =IFERROR(VLOOKUP(B255, 'Price Data'!A:D, 3, FALSE) * VLOOKUP(B255, 'Price Data'!A:D, 4, FALSE) * C255, "")
A256: 45736 | B256: ING-061 | C256: 1 | D256: Hot Hold | E256: Maybe | F256: Temp. logs req. | G256: =IFERROR(VLOOKUP(B256, 'Price Data'!A:D, 3, FALSE) * VLOOKUP(B256, 'Price Data'!A:D, 4, FALSE) * C256, "")
...

Sheet Price Data
A1: Food Item | B1: Unit Weight (grams) | C1: Servings per Unit | D1: Potential Revenue per Serving ($) | E1: Price Confidence | F1: Operational Role | G1: Dishes | H1: Food Category
A2: ING-098 | B2: 142 | C2: 7.5 | D2: 0.89 | E2: 3.5 | F2: Support Component | G2: DISH-104 [.95] | DISH-069 [.05] | H2: Red Meat
A3: ING-129 | B3: 336.5 | C3: 1 | D3: 5.66 | E3: 4.5 | F3: Core Component | G3: DISH-058 [.5] | DISH-036 [.5] | H3: Starches
A4: ING-058 | B4: 399.4 | C4: 1 | D4: 10.06 | E4: 4 | F4: Core Component | G4: DISH-106 [.25] | DISH-013 [.25] | DISH-040 [.25] | DISH-024 [.25] | H4: Grains
A5: ING-021 | B5: 285 | C5: 1 | D5: 5.04 | E5: 5 | F5: Core Component | G5: DISH-007 [1] | H5: Legumes
A6: ING-137 | B6: 509.8 | C6: 1 | D6: 15.35 | E6: 4.5 | F6: Core Component | G6: DISH-110 [1] | H6: Red Meat | Vegetables
A7: ING-142 | B7: 267.7 | C7: 1 | D7: 15.45 | E7: 4.5 | F7: Core Component | G7: DISH-061 [1] | H7: Red Meat
A8: ING-067 | B8: 535.7 | C8: 1 | D8: 17.5 | E8: 5 | F8: Core Component | G8: DISH-052 [1] | H8: Red Meat | Sauces & Condiments
A9: ING-110 | B9: 450.3 | C9: 3 | D9: 5.51 | E9: 4.5 | F9: Modular Protein | G9: DISH-040 [.75] | DISH-010 [.125] | DISH-042 [.125] | H9: Red Meat
A10: ING-089 | B10: 457.4 | C10: 3 | D10: 4.36 | E10: 4.5 | F10: Modular Protein | G10: DISH-102 [.35] | DISH-056 [.4] | DISH-120 [.125] | DISH-101 [.125] | H10: Poultry
A11: ING-127 | B11: 507.5 | C11: 1 | D11: 9.44 | E11: 5 | F11: Variant Driver | G11: DISH-122 [1] | H11: Sauces & Condiments
A12: ING-109 | B12: 4306.2 | C12: 18 | D12: 12.4 | E12: 4 | F12: Core Component | G12: DISH-011 [.75] | DISH-054 [.25] | H12: Poultry
A13: ING-048 | B13: 4697.4 | C13: 21 | D13: 9.71 | E13: 4 | F13: Core Component | G13: DISH-022 [.75] | DISH-079 [.25] | H13: Poultry
... A143: ING-042 | B143: 919 | C143: 15 | D143: 0.57 | E143: 3 | F143: Condiment/Spread | G143: DISH-028 [1] | H143: Sauces & Condiments

Sheet Menu Anchors
A1: Menu Item | B1: Menu Price ($) | C1: Ingredients | D1: % of Menu Price
A2: DISH-115 | B2: 21.99 | C2: ING-164 (2x) | ING-041 | ING-121 | ING-173 | D2: .65 | .2 | .10 | .05
A3: DISH-023 | B3: 17.99 | C3: ING-164 | ING-184 | ING-173 | D3: .60 | .35 | .05
A4: DISH-055 | B4: 9.99 | C4: ING-029 | ING-105 | ING-064 | ING-173 | D4: .8 | .15 | 0 | .05
A5: DISH-059 | B5: 18.99 | C5: ING-135 | ING-069 | ING-025 | ING-173 | D5: .55 | .35 | .05 | .05
A6: DISH-058 | B6: 9.99 | C6: ING-129 | ING-116 | ING-098 | ING-026 | D6: .55 | .2 | .15 | .1
A7: DISH-036 | B7: 8.99 | C7: ING-129 | ING-084 | ING-098 | ING-138 | D7: .55 | .2 | .15 | .1
A8: DISH-114 | B8: 3.99 | C8: ING-157 | D8: 1
A9: DISH-031 | B9: 3.99 | C9: ING-157 | ING-004 | D9: .75 | .25
A10: DISH-007 | B10: 5.99 | C10: ING-021 | D10: 1
A11: DISH-011 | B11: 11.99 | C11: ING-109 | ING-166 | D11: .9 | .1
A12: DISH-054 | B12: 20.99 | C12: ING-109 | ING-166 | D12: .9 | .1
A13: DISH-022 | B13: 10.99 | C13: ING-048 | ING-166 | D13: .9 | .1
A14: DISH-079 | B14: 15.99 | C14: ING-048 | ING-166 | D14: .9 | .1
A15: DISH-018 | B15: 7.99 | C15: ING-108 | ING-166 | D15: .9 | .1
A16: DISH-081 | B16: 9.99 | C16: ING-108 | ING-166 | D16: .9 | .1
A17: DISH-100 | B17: 17.99 | C17: ING-034 | ING-081 | ING-066 | ING-140 | ING-033 | D17: .25 | .15 | .5 | .05 | .05
A18: DISH-102 | B18: 17.99 | C18: ING-034 | ING-081 | ING-089 | ING-140 | ING-033 | D18: .25 | .15 | .5 | .05 | .05
A19: DISH-127 | B19: 17.99 | C19: ING-034 | ING-081 | ING-115 | ING-140 | ING-033 | D19: .25 | .15 | .5 | .05 | .05
A20: DISH-093 | B20: 14.99 | C20: ING-132 | ING-143 | ING-122 | ING-066 | ING-101 | D20: .25 | .12 | .15 | .4 | .08
A21: DISH-056 | B21: 16.99 | C21: ING-132 | ING-143 | ING-122 | ING-089 | ING-101 | D21: .25 | .12 | .15 | .4 | .08
A22: DISH-037 | B22: 17.99 | C22: ING-132 | ING-143 | ING-122 | ING-115 | ING-101 | D22: .25 | .12 | .15 | .4 | .08
A23: DISH-057 | B23: 29.99 | C23: ING-061 | ING-065 | ING-117 | D23: .7 | .2 | .1
A24: DISH-098 | B24: 7.99 | C24: ING-028 | D24: 1
A25: DISH-082 | B25: 4.99 | C25: ING-028 | ING-128 | D25: 1 | 0
A26: DISH-012 | B26: 16.99 | C26: ING-028 | ING-144 | D26: .7 | .3
A27: DISH-051 | B27: 13.99 | C27: ING-120 | ING-001 | ING-153 | D27: .45 | .25 | .3
A28: DISH-016 | B28: 11.99 | C28: ING-182 | ING-035 | ING-018 | ING-119 | D28: .45 | .2 | .025 | .325
A29: DISH-083 | B29: 28.99 | C29: ING-010 | ING-044 | ING-079 | ING-078 | D29: .65 | .2 | .1 | .05
A30: DISH-095 | B30: 9.99 | C30: ING-068 | ING-144 | ING-183 | D30: .7 | .25 | .05
A31: DISH-109 | B31: 8.99 | C31: ING-068 | ING-050 | D31: .8 | .2
A32: DISH-017 | B32: 8.99 | C32: ING-060 | ING-173 | ING-147 | D32: .75 | .2 | .05
A33: DISH-025 | B33: 27.99 | C33: ING-095 | ING-166 | D33: .75 | .25
A34: DISH-103 | B34: 29.99 | C34: ING-095 | ING-133 | D34: .75 | .25
A35: DISH-009 | B35: 17.99 | C35: ING-086 | ING-115 | ING-162 | ING-094 | D35: .2 | .4 | .2 | .2
A36: DISH-113 | B36: 16.99 | C36: ING-036 | ING-130 | D36: .7 | .3
... A54: DISH-010 | B54: 17.99 | C54: ING-076 | ING-110 | ING-140 | D54: .5 | .45 | .05
A55: DISH-043 | B55: 4.99 | C55: ING-178 | D55: 1
A56: DISH-099 | B56: 4.99 | C56: ING-163 | ING-019 | ING-138 | D56: .6 | .35 | .05
A57: DISH-041 | B57: 3.99 | C57: ING-031 | ING-166 | D57: .9 | .1
...

Sheet Keys
A1: Data Log Key
A2: Donatable? | B2: Yes | C2: No | D2: Maybe | E2: Weak Maybe | F2: Strong Maybe
A5: PriceData Key
A6: OBTAINING PRICE:
A7: Method | B7: Description | C7: Used For Examples
A8: Direct Menu Price | B8: Item is sold standalone (e.g. [REDACTED], soup), if in multiple items, weigthed average based on prevalency | C8: [REDACTED]
A9: Menu Price Minus Known Add-ons | B9: Dish price minus other known component prices (sauce, rice, protein) | C9: [REDACTED]
A10: Variant Price Comparison | B10: Comparing variants (e.g. price with/without cheese or accompaniments) | C10: [REDACTED], [REDACTED]
A11: Standard Portion Attribution | B11: Assigning a % of dish price based on consistent build structure | C11: [REDACTED], Vodka Tortiglioni
A12: Ingredient Cost Distribution | B12: Manual estimate based on relative ingredient role in dish (rare use) | C12: Used cautiously for insignificant items—flagged with lower confidence
A14: PRICE CONFIDENCE: | B14: [DISCLAIMER]: prices are generally on the conservative side for fear of inflating results
A15: Rating | B15: Meaning | C15: When Used
A16: 5 | B16: Exact or near-exact match to menu pricing; clear breakdown of all components | C16: Known menu price & portion count; known sauce/protein/rice values
A17: 4.5 | B17: Very confident; most values known, some minor elements estimated (e.g. garnish) | C17: Dishes with minor unknowns like sauce, herbs, or unknown drizzle weights
A18: 4 | B18: Reasonable estimate based on consistent logic, but some uncertainty remains | C18: Multiple variable components; no clear itemized breakdown
A19: 3 | B19: Rough estimate using average or assumed values; servings not itemized or weighed | C19: Legacy items, low-selling dishes, bundles without precise structure
A20: 1–2 | B20: Guesswork or placeholder; no structured breakdown yet | C20: Avoided unless explicitly marked during scoping phase
A22: Operational Role | B22: Meaning | C22: Examples
A23: Core Component | B23: Defines the identity of a menu item. If it’s missing, the item is OOS. | C23: [REDACTED]
A24: Variant Driver | B24: Defines a named variant of a base dish. Removable, but changes name. | C24: [REDACTED]
A25: Base/Carrier | B25: The structural platform for dishes. Not called out, but needed. | C25: [REDACTED]
A26: Support Component | B26: Adds flavor, texture, or value. Swappable or optional. | C26: [REDACTED]
A27: Condiment/Spread | B27: Dips, drizzles, and spreads used on the side or top. Often optional. | C27: [REDACTED]

Sheet Interchangeable
A1: Group | B1: Item
A2: 1 | B2: ING-044
A3: 1 | B3: ING-113
